Workbook

Sheet REGISTROS
A1: Fecha | B1: Tipo | C1: Area | D1: Proyecto | E1: Descripcion | F1: Valor | G1: Metodo | H1: Responsable
A2: 46122 | B2: Entrada | C2: Consultoría | D2: Copornor | E2: Corponor | F2: 3038000
A3: 46122 | B3: Gasto | C3: Personal | D3: Supervivencia | E3: Gestavit | F3: 173565
A4: 46122 | B4: Gasto | C4: Yogurt | D4: Yogurt | E4: Leche Yogurt | F4: 29420
A5: 46122 | B5: Gasto | C5: Personal | D5: Personal | E5: Pechuga de pollo | F5: 30033
A6: 46122 | B6: Gasto | C6: Personal | D6: Personal | E6: Empanadas | F6: 8000
A7: 46123 | B7: Gasto | C7: Personal | D7: Personal | E7: Salchipapa-Perro caliente | F7: 28000
A8: 46124 | B8: Gasto | C8: Consultoría | D8: Copornor | E8: Chucherias y dulces | F8: 50300
A9: 46124 | B9: Gasto | C9: Consultoría | D9: Copornor | E9: Cuenta de telefono | F9: 41400
A10: 46124 | B10: Gasto | C10: Personal | D10: Personal | E10: Maracuya | F10: 7000
A11: 46124 | B11: Gasto | C11: Personal | D11: Personal | E11: Papa, ajo, bananos | F11: 14800
A12: 46124 | B12: Gasto | C12: Personal | D12: Personal | E12: Jabon aseo personal, crema de leche, maiz | F12: 62400
A13: 46124 | B13: Gasto | C13: Personal | D13: Personal | E13: Lechuga, tomate, queso | F13: 30700
... A30: 46128 | B30: Gasto | C30: Consultoría | D30: San Roque | E30: Baterias GPS | F30: 5000
A31: 46128 | B31: Gasto | C31: Personal | E31: Transportes Pareja | F31: 30000
A32: 46128 | B32: Gasto | C32: Consultoría | D32: Trabajo Sacyr | E32: Gasolina | F32: 18346
A33: 46129 | B33: Gasto | C33: Personal | E33: Transportes Pareja | F33: 9000
A34: 46129 | B34: Gasto | C34: Personal | E34: Transportes Pareja | F34: 3000
A35: 46129 | B35: Gasto | C35: Personal | E35: Almuerzo pollo broaster | F35: 13000
A36: 46129 | B36: Gasto | C36: Consultoría | D36: Trabajo Sacyr | E36: Gasolina | F36: 21447
A37: 46130 | B37: Gasto | C37: Consultoría | D37: Trabajo Sacyr | E37: Gasolina | F37: 25354
A38: 46130 | B38: Gasto | C38: Consultoría | E38: Almuerzos Jose y Rovert | F38: 50000
A39: 46130 | B39: Gasto | C39: Personal | E39: Arepas rellenas | F39: 15500
A40: 46130 | B40: Gasto | C40: Personal | E40: Mantecadas, queso regalos | F40: 27000
A41: 46130 | B41: Gasto | C41: Personal | E41: Rifa Sobrinas | F41: 20000
A42: 46130 | B42: Gasto | C42: Personal | E42: Chawarma Leidy | F42: 14000
A43: 46131 | B43: Gasto | C43: Personal | E43: Toallas Higienicas | F43: 4000
A44: 46132 | B44: Gasto | C44: Consultoría | D44: Trabajo Sacyr | E44: Cigarros | F44: 10000
A45: 46132 | B45: Gasto | C45: Yogurt | D45: Negocio Yogurt | E45: Embases Yogurt | F45: 32400
A46: 46132 | B46: Gasto | C46: Yogurt | D46: Negocio Yogurt | E46: Leche Yogurt | F46: 8000
A47: 46132 | B47: Gasto | C47: Yogurt | D47: Negocio Yogurt | E47: Azucar mora chocolate mermelada | F47: 17200
A48: 46132 | B48: Gasto | C48: Yogurt | D48: Negocio Yogurt | E48: Cultivo lactico | F48: 50000
A49: 46131 | B49: Entrada | C49: Yogurt | D49: Negocio Yogurt | E49: Yogurt Camilo | F49: 45000
A50: 46133 | B50: Gasto | C50: Personal | E50: Almuerzo | F50: 28000
A51: 46133 | B51: Gasto | C51: Personal | E51: Prestamo Jair | F51: 279000
A52: 46133 | B52: Entrada | C52: Consultoría | E52: Trabajo Sacyr | F52: 1250000
A53: 46134 | B53: Gasto | C53: Consultoría | D53: Trabajo San Roque | E53: Linternas | F53: 135000
A54: 46134 | B54: Gasto | C54: Consultoría | D54: Trabajo San Roque | E54: Silla tactica | F54: 35000
A55: 46134 | B55: Gasto | C55: Consultoría | D55: Trabajo San Roque | E55: Cigarros | F55: 40000
A56: 46134 | B56: Gasto | C56: Consultoría | D56: Trabajo San Roque | E56: Farmacia | F56: 25000
...

Sheet DASHBOARD
A1: SISTEMA FINANCIERO PERSONAL Y PROFESIONAL
A5: Dinero Total | B5: =SUMIF(REGISTROS!B:B,"Entrada",REGISTROS!F:F)-SUMIF(REGISTROS!B:B,"Gasto",REGISTROS!F:F) -> 2411637 | D5: Distribución Recomendada
A6: Entradas Totales | B6: =SUMIF(REGISTROS!B:B,"Entrada",REGISTROS!F:F) -> 8457000 | D6: Operación 40% | E6: =B5*0.4 -> 964654.8
A7: Gastos Totales | B7: =SUMIF(REGISTROS!B:B,"Gasto",REGISTROS!F:F) -> 6045363 | D7: Personal 30% | E7: =B5*0.3 -> 723491.1
A8: Consultoría | B8: =SUMIFS(REGISTROS!F:F,REGISTROS!C:C,"Consultoría",REGISTROS!B:B,"Entrada")-SUMIFS(REGISTROS!F:F,REGISTROS!C:C,"Consultoría",REGISTROS!B:B,"Gasto") -> 4398896 | D8: Ahorro 20% | E8: =B5*0.2 -> 482327.4
A9: Yogurt | B9: =SUMIFS(REGISTROS!F:F,REGISTROS!C:C,"Yogurt",REGISTROS!B:B,"Entrada")-SUMIFS(REGISTROS!F:F,REGISTROS!C:C,"Yogurt",REGISTROS!B:B,"Gasto") -> 206440 | D9: Yogurt 10% | E9: =B5*0.1 -> 241163.7
A10: Personal | B10: =SUMIFS(REGISTROS!F:F,REGISTROS!C:C,"Personal",REGISTROS!B:B,"Gasto") -> 2227699

Sheet CONSULTORIA
A1: ANALISIS CONSULTORIA
A5: Proyecto | B5: Ingresos | C5: Gastos | D5: Utilidad | E5: Margen
A6: Corponor | B6: =SUMIFS(REGISTROS!F:F,REGISTROS!D:D,"Corponor",REGISTROS!B:B,"Entrada") -> 0 | C6: =SUMIFS(REGISTROS!F:F,REGISTROS!D:D,"Corponor",REGISTROS!B:B,"Gasto") -> 0 | D6: =B6-C6 -> 0 | E6: =IF(B6=0,0,D6/B6) -> 0
A7: Sacyr | B7: =SUMIFS(REGISTROS!F:F,REGISTROS!D:D,"Sacyr",REGISTROS!B:B,"Entrada") -> 0 | C7: =SUMIFS(REGISTROS!F:F,REGISTROS!D:D,"Sacyr",REGISTROS!B:B,"Gasto") -> 104557 | D7: =B7-C7 -> -104557 | E7: =IF(B7=0,0,D7/B7) -> 0
A8: San Roque | B8: =SUMIFS(REGISTROS!F:F,REGISTROS!D:D,"San Roque",REGISTROS!B:B,"Entrada") -> 0 | C8: =SUMIFS(REGISTROS!F:F,REGISTROS!D:D,"San Roque",REGISTROS!B:B,"Gasto") -> 5000 | D8: =B8-C8 -> -5000 | E8: =IF(B8=0,0,D8/B8) -> 0

Sheet YOGURT
A1: NEGOCIO YOGURT
A5: Indicador | B5: Valor
A6: Ingresos | B6: =SUMIFS(REGISTROS!F:F,REGISTROS!C:C,"Yogurt",REGISTROS!B:B,"Entrada") -> 509000
A7: Gastos | B7: =SUMIFS(REGISTROS!F:F,REGISTROS!C:C,"Yogurt",REGISTROS!B:B,"Gasto") -> 302560
A8: Utilidad | B8: =B6-B7 -> 206440
A9: Margen | B9: =IF(B6=0,0,B8/B6) -> 0.40557957
A10: Reinversión sugerida | B10: =B8*0.4 -> 82576

Sheet PERSONAL
A1: VIDA PERSONAL Y BIENESTAR
A5: Categoría | B5: Valor
A6: Pareja | B6: =SUMIFS(REGISTROS!F:F,REGISTROS!D:D,"Pareja") -> 0
A7: Bienestar | B7: =SUMIFS(REGISTROS!F:F,REGISTROS!D:D,"Bienestar") -> 0
A8: Social | B8: =SUMIFS(REGISTROS!F:F,REGISTROS!D:D,"Social") -> 0
A9: Descanso | B9: =SUMIFS(REGISTROS!F:F,REGISTROS!D:D,"Descanso") -> 0
A10: Emocional | B10: =SUMIFS(REGISTROS!F:F,REGISTROS!D:D,"Emocional") -> 0

Sheet PRESUPUESTO
A1: PRESUPUESTO KAKEIBO
A5: Categoría | B5: Presupuesto | C5: Real | D5: Diferencia
A6: Supervivencia | B6: 1200000 | C6: =SUMIF(REGISTROS!B:B,"Gasto",REGISTROS!F:F) -> 6045363 | D6: =B6-C6 -> -4845363
A7: Operación | B7: 800000 | C7: =SUMIF(REGISTROS!B:B,"Gasto",REGISTROS!F:F) -> 6045363 | D7: =B7-C7 -> -5245363
A8: Crecimiento | B8: 500000 | C8: =SUMIF(REGISTROS!B:B,"Gasto",REGISTROS!F:F) -> 6045363 | D8: =B8-C8 -> -5545363
A9: Bienestar | B9: 300000 | C9: =SUMIF(REGISTROS!B:B,"Gasto",REGISTROS!F:F) -> 6045363 | D9: =B9-C9 -> -5745363

Sheet METAS
A1: CRECIMIENTO Y FUTURO
A5: Meta | B5: Objetivo | C5: Ahorrado | D5: Faltante | E5: %
A6: Fondo Emergencia | B6: 5000000 | C6: =DASHBOARD!E8 -> 482327.4 | D6: =B6-C6 -> 4517672.6 | E6: =C6/B6 -> 0.09646548
A7: Posgrado | B7: 25000000 | C7: =DASHBOARD!E8 -> 482327.4 | D7: =B7-C7 -> 24517673 | E7: =C7/B7 -> 0.019293096
A8: Laptop SIG | B8: 4500000 | C8: =DASHBOARD!E8 -> 482327.4 | D8: =B8-C8 -> 4017672.6 | E8: =C8/B8 -> 0.10718387
A9: Equipos Campo | B9: 3200000 | C9: =DASHBOARD!E8 -> 482327.4 | D9: =B9-C9 -> 2717672.6 | E9: =C9/B9 -> 0.15072731
